Workbook
Name Sab: #REF!
Name Car: #REF!
Name Prof: #REF!
Name For: #REF!
Name Dex: #REF!
Name Int: #REF!
Name Con: #REF!

Sheet Ficha
B2: Nome: | D2: Sasuke | J2: Classe: | M2: Ninja Batedor | V2: Level | X2: Prof | AM2: Livros
V3: 1 | X3: =2+ROUNDUP(V3/3,0) -> 3 | AM3: Manual shinobi
B4: Clã: | D4: Uchiha | J4: Sub-Classe: | AM4: Estudos da Tsunade
AA5: VONTADE DO | AM5: Observações do Orochimaru
B6: Equipe: | J6: Mod. Classe: | V6: XP | X6: XP Max | AB6: 3 | AM6: Anotações do Jiraya
V7: 0 | X7: =IF(ISNUMBER(V3),if(AND(V3>=1,V3<=20),CHOOSE(V3,50,75,100,150,200,350,475,600,725,850,1000,1200,1400,1600,1800,2100,2400,2700,3000),0),0) -> 50 | AM7: Poderes Secretos
B8: Vila: | J8: Antecedente: | M8: Estudante | AA8: FOGO
B10: Atibutos | G10: Testes de Salvamentos (CD) | O10: FALSE | P10: 0 | Q10: FALSE | W10: Total | Y10: 30 | AC10: Teste de Morte | AM10: Vida por Turno | AW10: Chakra por Turno
G11: =IF(OR(M2="Ninja Médico", M2="Ninja Batedor", M2="Especialista em Taijutsu", M2="Especialista em Armas", M2="Mestre da Marionetes"), 1, "h") -> 1 | H11: =IF(AP2="h",FLOOR(0.5*X3,1),IF(G11="e",2*X3,IF(G11=1,X3,0)))+C13+Modificadores!B23+Modificadores!B29 -> 3 | I11: Força | O11: =If(P10=+1,C28,IF(P10=-1,C33,C18))+if(O10=true,X3,(ROUNDDOWN(X3/2,0)))+IF(Q10=true,5,0)+O14+Modificadores!B8 -> 2 | S11: ='Registro e Inventário'!AM4 -> 19 | W11: Base | Y11: 30 | AC11: Sucesso | AH11: FALSE | AI11: TRUE | AJ11: TRUE | AM11: Turno | AO11: ="+ PV" -> + PV | AQ11: ="- PV" -> - PV | AS11: ="+ PVT" -> + PVT | AU11: ="- PVT" -> - PVT | AW11: Turno | AY11: ="+ PC" -> + PC | BA11: ="- PC" -> - PC | BC11: ="+ PCT" -> + PCT | BE11: ="- PCT" -> - PCT
C12: FOR | G12: =IF(OR(M2="Ninja Cientista", M2="Especialista em Taijutsu", M2="Especialista em Armas", M2="Operativo de Inteligência", M2="Ninja Caçador"), 1, "h") -> h | H12: =IF(G12="h",FLOOR(0.5*X3,1),IF(G12="e",2*X3,IF(G12=1,X3,0)))+C18+Modificadores!B24+Modificadores!B29 -> 2 | I12: Destreza | W12: Bônus
C13: =IF(C15>=10,ROUNDDOWN((C15-10)/2,0),ROUNDUP((C15-10)/2,0)) -> 0 | G13: =IF(OR(M2="Ninja Cientista", M2="Ninja Batedor", M2="Especialista em Genjutsu", M2="Especialista em Armas", M2="Ninja Cozinheiro", M2="Mestre da Marionetes"), 1, "h") -> 1 | H13: =IF(G13="h",FLOOR(0.5*X3,1),IF(G13="e",2*X3,IF(G13=1,X3,0)))+C23+Modificadores!B25+Modificadores!B29 -> 4 | I13: Constituição | O13: INICIATIVA | S13: CA | W13: Impulso | Y13: FALSE | Z13: FALSE | AA13: FALSE | AC13: Falhas | AH13: FALSE | AI13: TRUE | AJ13: TRUE | AM13: Salvo | AS13: 5 | AW13: Salvo
G14: =IF(OR(M2="Ninja Cientista", M2="Ninja Batedor", M2="Especialista em Ninjutsu", M2="Operativo de Inteligência", M2="Ninja Cozinheiro", M2="Mestre da Marionetes", M2="Ninja Caçador"), 1, "h") -> 1 | H14: =IF(G14="h",FLOOR(0.5*X3,1),IF(G14="e",2*X3,IF(G14=1,X3,0)))+C28+Modificadores!B26+Modificadores!B29 -> 6 | I14: Inteligência | O14: 0 | S14: 0 | W14: Calc de Movimento | AM14: 1 | AQ14: 0 | AW14: 1 | BA14: 6
C15: 11 | G15: =IF(OR(M2="Ninja Médico", M2="Ninja Caçador", M2="Especialista em Ninjutsu", M2="Especialista em Genjutsu"), 1, "h") -> h | H15: =IF(G15="h",FLOOR(0.5*X3,1),IF(G15="e",2*X3,IF(G15=1,X3,0)))+C33+Modificadores!B27+Modificadores!B29 -> 1 | I15: Sabedoria | AM15: 2 | AW15: 2
C16: 0 | G16: =IF(OR(M2="Ninja Médico", M2="Operativo de Inteligência", M2="Especialista em Taijutsu", M2="Especialista em Ninjutsu", M2="Especialista em Genjutsu", M2="Ninja Cozinheiro"), 1, "h") -> h | H16: =IF(G16="h",FLOOR(0.5*X3,1),IF(G16="e",2*X3,IF(G16=1,X3,0)))+C38+Modificadores!B28+Modificadores!B29 -> 3 | I16: Carisma | O16: PV Max: | Q16: =SUM(Modificadores!D4+V28+C23+P21+IF(O21=true,PRODUCT(SUM(V3-1),V28+C23),PRODUCT(SUM(V3-1),V28/2+1+C23+P21))) -> 19 | S16: =IFERROR(__xludf.DUMMYFUNCTION("SPARKLINE(O18,{""charttype"",""column"";""ymax"",Q16;""ymin"",0;""color"",IF(O18>ROUND(Q16*0.6),""green"",IF(O18<ROUND(Q16*0.2),""red"",""yellow""))})"),"") | T16: =IFERROR(__xludf.DUMMYFUNCTION("SPARKLINE(U18,{""charttype"",""column"";""ymax"",W16;""ymin"",0;""color"",""blue""})"),"") | U16: PC Max: | W16: =SUM(Modificadores!D4+Z28+C23+V21+IF(U21=true,PRODUCT(SUM(V3-1),Z28+C23),PRODUCT(SUM(V3-1),Z28/2+1+C23+V21))) -> 21 | Z16: NIN | AC16: GEN | AF16: TAI | AM16: 3 | AW16: 3
C17: DES | Z17: =Jutsus!U3 -> 6 | AC17: =Jutsus!AA3 -> 5 | AF17: =Jutsus!AG3 -> 3 | AM17: 4 | AW17: 4
C18: =IF(C20>=10,ROUNDDOWN((C20-10)/2,0),ROUNDUP((C20-10)/2,0)) -> 1 | G18: PERICIAS | O18: =MIN(Q16,Q16-AQ25+AO25) -> 19 | U18: =MIN(W16,W16-BA25+AY25) -> 15 | AM18: 5 | AW18: 5
G19: 1 | H19: =IF(M19="For",C13,IF(M19="Des",C18,IF(M19="Con",C23,IF(M19="Int",C28,IF(M19="Sab",C33,IF(M19="Car",C38,0)))))) + IF(G19="h",ROUNDDOWN(X3 * 0.5, 0),IF(G19=1,X3,IF(G19="m",X3*2,IF(G19="m1",X3+2,IF(G19="m2",X3+4,IF(G19="m3",X3+6,0))))))+Modificadores!B30+Modificadores!B51 -> 4 | I19: Acrobacia | M19: Des | Z19: =Jutsus!S3 -> 14 | AC19: =Jutsus!Y3 -> 13 | AF19: =Jutsus!AE3 -> 11 | AM19: 6 | AW19: 6
C20: 13 | G20: 0 | H20: =IF(M20="For",C13,IF(M20="Des",C18,IF(M20="Con",C23,IF(M20="Int",C28,IF(M20="Sab",C33,IF(M20="Car",C38,0)))))) + IF(G20="h",ROUNDDOWN(X3 * 0.5, 0),IF(G20=1,X3,IF(G20="m",X3*2,IF(G20="m1",X3+2,IF(G20="m2",X3+4,IF(G20="m3",X3+6,0))))))+Modificadores!B31+Modificadores!B51 -> 0 | I20: Adestrar Animais | M20: Sab | O20: Pontos de Vida Atual | U20: Pontos de Chakra Atual | AM20: 7 | AW20: 7
C21: 0 | G21: 1 | H21: =IF(M21="For",C13,IF(M21="Des",C18,IF(M21="Con",C23,IF(M21="Int",C28,IF(M21="Sab",C33,IF(M21="Car",C38,0)))))) + IF(G21="h",ROUNDDOWN(X3 * 0.5, 0),IF(G21=1,X3,IF(G21="m",X3*2,IF(G21="m1",X3+2,IF(G21="m2",X3+4,IF(G21="m3",X3+6,0))))))+Modificadores!B32+Modificadores!B51 -> 3 | I21: Artes Marciais | M21: For | O21: TRUE | P21: 0 | U21: FALSE | V21: 0 | Z21: CD NIN | AC21: CD GEN | AF21: CD TAI | AM21: 8 | AW21: 8
C22: CON | G22: 0 | H22: =IF(M22="For",C13,IF(M22="Des",C18,IF(M22="Con",C23,IF(M22="Int",C28,IF(M22="Sab",C33,IF(M22="Car",C38,0)))))) + IF(G22="h",ROUNDDOWN(X3 * 0.5, 0),IF(G22=1,X3,IF(G22="m",X3*2,IF(G22="m1",X3+2,IF(G22="m2",X3+4,IF(G22="m3",X3+6,0))))))+Modificadores!B33+Modificadores!B51 -> 0 | I22: Atletismo | M22: For | O22: =AS25-AU25 -> 5 | U22: =BC25-BE25 -> 0 | AM22: 9 | AW22: 9
C23: =IF(C25>=10,ROUNDDOWN((C25-10)/2,0),ROUNDUP((C25-10)/2,0)) -> 1 | G23: 0 | H23: =IF(M23="For",C13,IF(M23="Des",C18,IF(M23="Con",C23,IF(M23="Int",C28,IF(M23="Sab",C33,IF(M23="Car",C38,0)))))) + IF(G23="h",ROUNDDOWN(X3 * 0.5, 0),IF(G23=1,X3,IF(G23="m",X3*2,IF(G23="m1",X3+2,IF(G23="m2",X3+4,IF(G23="m3",X3+6,0))))))+Modificadores!B34+Modificadores!B51 -> 3 | I23: Construir | M23: Int | Z23: Base de Ataque | AE23: For | AG23: =IF(AE23="For",C13,IF(AE23="Des",Ficha!C18,IF(AE23="Con",Ficha!C23,IF(AE23="Int",Ficha!C28,IF(AE23="Sab",Ficha!C33,Ficha!X16,IF(AE23="Car",Ficha!C38,Ficha!X16))))))+X3 -> 3 | AM23: 10 | AW23: 10
G24: 1 | H24: =IF(M24="For",C13,IF(M24="Des",C18,IF(M24="Con",C23,IF(M24="Int",C28,IF(M24="Sab",C33,IF(M24="Car",C38,0)))))) + IF(G24="h",ROUNDDOWN(X3 * 0.5, 0),IF(G24=1,X3,IF(G24="m",X3*2,IF(G24="m1",X3+2,IF(G24="m2",X3+4,IF(G24="m3",X3+6,0))))))+Modificadores!B35+Modificadores!B51 -> 4 | I24: Controle de Chakra | M24: Con | O24: PV TEMP. | U24: PC TEMP. | Z24: (Arma ou Punho) | AM24: Salvo | AQ24: 10 | AW24: Salvo
C25: 12 | G25: 0 | H25: =IF(M25="For",C13,IF(M25="Des",C18,IF(M25="Con",C23,IF(M25="Int",C28,IF(M25="Sab",C33,IF(M25="Car",C38,0)))))) + IF(G25="h",ROUNDDOWN(X3 * 0.5, 0),IF(G25=1,X3,IF(G25="m",X3*2,IF(G25="m1",X3+2,IF(G25="m2",X3+4,IF(G25="m3",X3+6,0))))))+Modificadores!B36+Modificadores!B51 -> 2 | I25: Enganação | M25: Car | AM25: Totais | AO25: =SUM(AO13:AP23) -> 0 | AQ25: =SUM(AQ13:AR23) -> 0 | AS25: =SUM(AS13:AT23) -> 5 | AU25: =SUM(AU13:AV23) -> 0 | AW25: Totais | AY25: =SUM(AY13:AZ23) -> 0 | BA25: =SUM(BA13:BB23) -> 6 | BC25: =SUM(BC13:BD23) -> 0 | BE25: =SUM(BE13:BF23) -> 0
C26: 0 | G26: 1 | H26: =IF(M26="For",C13,IF(M26="Des",C18,IF(M26="Con",C23,IF(M26="Int",C28,IF(M26="Sab",C33,IF(M26="Car",C38,0)))))) + IF(G26="h",ROUNDDOWN(X3 * 0.5, 0),IF(G26=1,X3,IF(G26="m",X3*2,IF(G26="m1",X3+2,IF(G26="m2",X3+4,IF(G26="m3",X3+6,0))))))+Modificadores!B37+Modificadores!B51 -> 4 | I26: Furtividade | M26: Des | T26: Dados
C27: INT | G27: 0 | H27: =IF(M27="For",C13,IF(M27="Des",C18,IF(M27="Con",C23,IF(M27="Int",C28,IF(M27="Sab",C33,IF(M27="Car",C38,0)))))) + IF(G27="h",ROUNDDOWN(X3 * 0.5, 0),IF(G27=1,X3,IF(G27="m",X3*2,IF(G27="m1",X3+2,IF(G27="m2",X3+4,IF(G27="m3",X3+6,0))))))+Modificadores!B38+Modificadores!B51 -> 3 | I27: História | M27: Int | T27: Vida | X27: Chakra | AB27: Classe
C28: =IF(C30>=10,ROUNDDOWN((C30-10)/2,0),ROUNDUP((C30-10)/2,0)) -> 3 | G28: 1 | H28: =IF(M28="For",C13,IF(M28="Des",C18,IF(M28="Con",C23,IF(M28="Int",C28,IF(M28="Sab",C33,IF(M28="Car",C38,0)))))) + IF(G28="h",ROUNDDOWN(X3 * 0.5, 0),IF(G28=1,X3,IF(G28="m",X3*2,IF(G28="m1",X3+2,IF(G28="m2",X3+4,IF(G28="m3",X3+6,0))))))+Modificadores!B39+Modificadores!B51 -> 3 | I28: Ilusão | M28: Sab | T28: =V3+Modificadores!B5 -> 1 | U28: d | V28: =VLOOKUP(M2,'Banco de Dados'!A237:AB249,27,0) -> 8 | X28: =V3+Modificadores!F6 -> 1 | Y28: d | Z28: =VLOOKUP(M2,'Banco de Dados'!A237:AB249,28,0) -> 10 | AB28: d | AC28: 4 | AM28: Condições Ativas
G29: 0 | H29: =IF(M29="For",C13,IF(M29="Des",C18,IF(M29="Con",C23,IF(M29="Int",C28,IF(M29="Sab",C33,IF(M29="Car",C38,0)))))) + IF(G29="h",ROUNDDOWN(X3 * 0.5, 0),IF(G29=1,X3,IF(G29="m",X3*2,IF(G29="m1",X3+2,IF(G29="m2",X3+4,IF(G29="m3",X3+6,0))))))+Modificadores!B40+Modificadores!B51 -> 2 | I29: Intimidação | M29: Car | AM29: Ativo | AO29: Rank | AQ29: Nome da Condição | AU29: Ativo | AW29: Rank | AY29: Nome da Condição
C30: 16 | G30: 1 | H30: =IF(M30="For",C13,IF(M30="Des",C18,IF(M30="Con",C23,IF(M30="Int",C28,IF(M30="Sab",C33,IF(M30="Car",C38,0)))))) + IF(G30="h",ROUNDDOWN(X3 * 0.5, 0),IF(G30=1,X3,IF(G30="m",X3*2,IF(G30="m1",X3+2,IF(G30="m2",X3+4,IF(G30="m3",X3+6,0))))))+Modificadores!B41+Modificadores!B51 -> 3 | I30: Intuição | M30: Sab | AM30: Fisico | AN30: FALSE | AO30: 1 | AQ30: Ferida | AU30: Elemental | AV30: FALSE | AW30: 1 | AY30: Queimado
C31: 0 | G31: 0 | H31: =IF(M31="For",C13,IF(M31="Des",C18,IF(M31="Con",C23,IF(M31="Int",C28,IF(M31="Sab",C33,IF(M31="Car",C38,0)))))) + IF(G31="h",ROUNDDOWN(X3 * 0.5, 0),IF(G31=1,X3,IF(G31="m",X3*2,IF(G31="m1",X3+2,IF(G31="m2",X3+4,IF(G31="m3",X3+6,0))))))+Modificadores!B42+Modificadores!B51 -> 3 | I31: Investigação | M31: Int | AN31: FALSE | AO31: 1 | AQ31: Cambaleante | AV31: FALSE | AW31: 1 | AY31: Resfriado
C32: SAB | G32: 0 | H32: =IF(M32="For",C13,IF(M32="Des",C18,IF(M32="Con",C23,IF(M32="Int",C28,IF(M32="Sab",C33,IF(M32="Car",C38,0)))))) + IF(G32="h",ROUNDDOWN(X3 * 0.5, 0),IF(G32=1,X3,IF(G32="m",X3*2,IF(G32="m1",X3+2,IF(G32="m2",X3+4,IF(G32="m3",X3+6,0))))))+Modificadores!B43+Modificadores!B51 -> 0 | I32: Medicina | M32: Sab | AN32: FALSE | AO32: 1 | AQ32: Sangramento | AV32: FALSE | AW32: 1 | AY32: Corroido
C33: =IF(C35>=10,ROUNDDOWN((C35-10)/2,0),ROUNDUP((C35-10)/2,0)) -> 0 | G33: 0 | H33: =IF(M33="For",C13,IF(M33="Des",C18,IF(M33="Con",C23,IF(M33="Int",C28,IF(M33="Sab",C33,IF(M33="Car",C38,0)))))) + IF(G33="h",ROUNDDOWN(X3 * 0.5, 0),IF(G33=1,X3,IF(G33="m",X3*2,IF(G33="m1",X3+2,IF(G33="m2",X3+4,IF(G33="m3",X3+6,0))))))+Modificadores!B44+Modificadores!B51 -> 3 | I33: Natureza | M33: Int | AN33: FALSE | AO33: 1 | AQ33: Lacerado | AV33: FALSE | AW33: 1 | AY33: Chocado
G34: 1 | H34: =IF(M34="For",C13,IF(M34="Des",C18,IF(M34="Con",C23,IF(M34="Int",C28,IF(M34="Sab",C33,IF(M34="Car",C38,0)))))) + IF(G34="h",ROUNDDOWN(X3 * 0.5, 0),IF(G34=1,X3,IF(G34="m",X3*2,IF(G34="m1",X3+2,IF(G34="m2",X3+4,IF(G34="m3",X3+6,0))))))+Modificadores!B45+Modificadores!B51 -> 6 | I34: Ninshou | M34: Int | O34: Passivas | AN34: FALSE | AO34: 1 | AQ34: Desnorteado | AV34: FALSE | AW34: 1 | AY34: Envenenado
C35: 11 | G35: 1 | H35: =IF(M35="For",C13,IF(M35="Des",C18,IF(M35="Con",C23,IF(M35="Int",C28,IF(M35="Sab",C33,IF(M35="Car",C38,0)))))) + IF(G35="h",ROUNDDOWN(X3 * 0.5, 0),IF(G35=1,X3,IF(G35="m",X3*2,IF(G35="m1",X3+2,IF(G35="m2",X3+4,IF(G35="m3",X3+6,0))))))+Modificadores!B46+Modificadores!B51 -> 3 | I35: Percepção | M35: Sab | O35: PASSIVA | S35: PASSIVA | W35: PASSIVA | AA35: PASSIVA | AN35: FALSE | AO35: 1 | AQ35: Agarrado | AU35: Sensorial | AV35: FALSE | AW35: 1 | AY35: Invisivel
C36: 0 | G36: 0 | H36: =IF(M36="For",C13,IF(M36="Des",C18,IF(M36="Con",C23,IF(M36="Int",C28,IF(M36="Sab",C33,IF(M36="Car",C38,0)))))) + IF(G36="h",ROUNDDOWN(X3 * 0.5, 0),IF(G36=1,X3,IF(G36="m",X3*2,IF(G36="m1",X3+2,IF(G36="m2",X3+4,IF(G36="m3",X3+6,0))))))+Modificadores!B47+Modificadores!B51 -> 2 | I36: Performance | M36: Car | P36: =H34+10 -> 16 | T36: =H29+10 -> 12 | X36: =H27+10 -> 13 | AB36: =H38+10 -> 11 | AN36: FALSE | AO36: 1 | AQ36: Derrubado | AV36: FALSE | AW36: 1 | AY36: Ofuscado
C37: CAR | G37: 0 | H37: =IF(M37="For",C13,IF(M37="Des",C18,IF(M37="Con",C23,IF(M37="Int",C28,IF(M37="Sab",C33,IF(M37="Car",C38,0)))))) + IF(G37="h",ROUNDDOWN(X3 * 0.5, 0),IF(G37=1,X3,IF(G37="m",X3*2,IF(G37="m1",X3+2,IF(G37="m2",X3+4,IF(G37="m3",X3+6,0))))))+Modificadores!B48+Modificadores!B51 -> 2 | I37: Persuasão | M37: Car | AN37: FALSE | AO37: 1 | AQ37: Restringido | AV37: FALSE | AW37: 1 | AY37: Surdo
C38: =IF(C40>=10,ROUNDDOWN((C40-10)/2,0),ROUNDUP((C40-10)/2,0)) -> 2 | G38: 0 | H38: =IF(M38="For",C13,IF(M38="Des",C18,IF(M38="Con",C23,IF(M38="Int",C28,IF(M38="Sab",C33,IF(M38="Car",C38,0)))))) + IF(G38="h",ROUNDDOWN(X3 * 0.5, 0),IF(G38=1,X3,IF(G38="m",X3*2,IF(G38="m1",X3+2,IF(G38="m2",X3+4,IF(G38="m3",X3+6,0))))))+Modificadores!B49+Modificadores!B51 -> 1 | I38: Prestidigitação | M38: Des | O38: PERCEPÇÃO | S38: INVESTIGAÇÃO | W38: INTUIÇÃO | AA38: FURTIVIDADE | AM38: Mental | AN38: FALSE | AO38: 1 | AQ38: Atordoado | AV38: FALSE | AW38: 1 | AY38: Cego
G39: 0 | H39: =IF(M39="For",C13,IF(M39="Des",C18,IF(M39="Con",C23,IF(M39="Int",C28,IF(M39="Sab",C33,IF(M39="Car",C38,0)))))) + IF(G39="h",ROUNDDOWN(X3 * 0.5, 0),IF(G39=1,X3,IF(G39="m",X3*2,IF(G39="m1",X3+2,IF(G39="m2",X3+4,IF(G39="m3",X3+6,0))))))+Modificadores!B50+Modificadores!B51 -> 0 | I39: Sobrevivência | M39: Sab | AN39: FALSE | AO39: 1 | AQ39: Enfraquecido | AU39: Variadas | AV39: FALSE | AW39: 1 | AY39: Morrendo
C40: 14 | H40: Recomendações em nota | O40: Armas | AN40: FALSE | AO40: 1 | AQ40: Fúria | AV40: FALSE | AW40: 1 | AY40: Incapacitado
C41: 0 | G41: Para colocar Proficiência coloque um "1" na célula, Para colocar Maestria coloque um "m" seguido do nível ex: "m1" | P41: Arma | W41: Prof | Y41: Dano | AA41: Descrição | AN41: FALSE | AO41: 1 | AQ41: Encantado | AV41: FALSE | AW41: 1 | AY41: Exaustão
P42: Kunai | W42: FALSE | Y42: =VLOOKUP(P42,'Banco de Dados'!A46:AQ118,8,0) -> 1d4 | AA42: =VLOOKUP(P42,'Banco de Dados'!A46:AQ118,35,0) -> Leve, Sutileza, Arremesso (30/60), Múltiplo ataque, munição | AN42: FALSE | AO42: 1 | AQ42: Concussão | AV42: FALSE | AW42: 1 | AY42: Inconsciênte
...

Sheet Registro e Inventário
B2: Nome | E2: =Ficha!D2 -> Sasuke | V2: INVENTÁRIO | AM2: Classe de Armadura
B4: Aparência | K4: Idade | V4: Nome do Item | AB4: Quant. | AD4: Efeito | AJ4: Peso | AM4: =SUM(AT4,AT5,AT6,AT7,AT8) -> 19 | AP4: Natural | AT4: 10
K5: Altura | N5: 145 | AP5: Armadura | AT5: =AC36 -> 5
K6: Peso | N6: 60 | AP6: Proficiência | AS6: TRUE | AT6: =IF(AS6=FALSE,Ficha!X3*0.5,IF(AS6=TRUE,Ficha!X3,"")) -> 3
K7: Gênero | AP7: Des | AT7: =IF(AP7="For",Ficha!C13,IF(AP7="Des",Ficha!C18,IF(AP7="Con",Ficha!C23,IF(AP7="Int",Ficha!C28,IF(AP7="Sab",Ficha!C33,Ficha!X16,IF(AP7="Car",Ficha!C38,Ficha!X16)))))) -> 1
K8: Cabelos | AM8: Total | AP8: Outros
K9: Olhos
K10: Pele | AM10: Bolsa
K11: Aura
K12: Roupas | AM12: Ocupados | AQ12: Limite
K13: Tamanho | AM13: =SUM(AF57) -> 0 | AQ13: =10+2*IF(Ficha!C13>0,Ficha!C13,0)+5 -> 15
K14: Marcas
B15: Idiomas
AM16: Ryos | AQ16: 100
B17: Traço do Antecedente
V18: Armas
V20: Arma | AB20: Bônus | AD20: Dano | AH20: Tipo | AK20: Descriçao
B21: Ambição | V21: Kunai | AD21: =VLOOKUP(V21,'Banco de Dados'!A46:AQ118,8,0) -> 1d4 | AH21: =VLOOKUP(V21,'Banco de Dados'!A46:AQ118,25,0) -> Perfuração | AK21: =VLOOKUP(V21,'Banco de Dados'!A46:AQ118,35,0) -> Leve, Sutileza, Arremesso (30/60), Múltiplo ataque, munição
V22: Shuriken Monstro | AD22: =VLOOKUP(V22,'Banco de Dados'!A46:AQ118,8,0) -> 1d12 | AH22: =VLOOKUP(V22,'Banco de Dados'!A47:AQ119,25,0) -> Contundente | AK22: =VLOOKUP(V22,'Banco de Dados'!A47:AQ119,35,0) -> Arremesso(40/80), Pesado, Duas Mãos, Retornável
V23: Senbon | AD23: =VLOOKUP(V23,'Banco de Dados'!A46:AQ118,8,0) -> 1d4 | AH23: =VLOOKUP(V23,'Banco de Dados'!A48:AQ120,25,0) -> Perfuração | AK23: =VLOOKUP(V23,'Banco de Dados'!A48:AQ120,35,0) -> Arremesso (30/60), Múltiplo ataque, munição
V24: Tanto (Espada Curta) | AD24: =VLOOKUP(V24,'Banco de Dados'!A46:AQ118,8,0) -> 1d6 | AH24: =VLOOKUP(V24,'Banco de Dados'!A49:AQ121,25,0) -> Cortante | AK24: =VLOOKUP(V24,'Banco de Dados'!A49:AQ121,35,0) -> Leve, Sutileza, Mortal, Flexível (Cortante d4)
B25: Motivação | V25: Shuriken | AD25: =VLOOKUP(V25,'Banco de Dados'!A46:AQ118,8,0) -> 1d4 | AH25: =VLOOKUP(V25,'Banco de Dados'!A50:AQ122,25,0) -> Contundente | AK25: =VLOOKUP(V25,'Banco de Dados'!A50:AQ122,35,0) -> Arremesso (30/120), Múltiplo ataque, munição
AD26: =VLOOKUP(V26,'Banco de Dados'!A46:AQ118,8,0) -> #N/A | AH26: =VLOOKUP(V26,'Banco de Dados'!A51:AQ123,25,0) -> #N/A | AK26: =VLOOKUP(V26,'Banco de Dados'!A51:AQ123,35,0) -> #N/A
AD27: =VLOOKUP(V27,'Banco de Dados'!A46:AQ118,8,0) -> #N/A | AH27: =VLOOKUP(V27,'Banco de Dados'!A52:AQ124,25,0) -> #N/A | AK27: =VLOOKUP(V27,'Banco de Dados'!A52:AQ124,35,0) -> #N/A
AD28: =VLOOKUP(V28,'Banco de Dados'!A46:AQ118,8,0) -> #N/A | AH28: =VLOOKUP(V28,'Banco de Dados'!A53:AQ125,25,0) -> #N/A | AK28: =VLOOKUP(V28,'Banco de Dados'!A53:AQ125,35,0) -> #N/A
B29: Meta | AD29: =VLOOKUP(V29,'Banco de Dados'!A46:AQ118,8,0) -> #N/A | AH29: =VLOOKUP(V29,'Banco de Dados'!A54:AQ126,25,0) -> #N/A | AK29: =VLOOKUP(V29,'Banco de Dados'!A54:AQ126,35,0) -> #N/A
B33: Medos | V33: Equipamento
V35: Armadura | AC35: Bônus CA | AF35: MOD | AI35: Tipo | AM35: Peso
V36: Jaqueta de combate Shinobi | AC36: =VLOOKUP(V36,'Banco de Dados'!A2:AF40,29,0) -> 5 | AF36: =VLOOKUP(V36,'Banco de Dados'!A2:AF40,13,0) -> DES | AI36: =VLOOKUP(V36,'Banco de Dados'!A2:AF40,7,0) -> Armadura Média | AM36: =VLOOKUP(V36,'Banco de Dados'!A2:AG40,33,0) -> 4
B37: História do Personagem | V37: Jaqueta de Combate | AC37: =VLOOKUP(V37,'Banco de Dados'!A2:AF40,29,0) -> 4 | AF37: =VLOOKUP(V37,'Banco de Dados'!A2:AF40,13,0) -> DES | AI37: =VLOOKUP(V37,'Banco de Dados'!A2:AF40,7,0) -> Armadura Média | AM37: =VLOOKUP(V37,'Banco de Dados'!A2:AI40,33,0) -> 4
AC38: =VLOOKUP(V38,'Banco de Dados'!A2:AF40,29,0) -> #N/A | AF38: =VLOOKUP(V38,'Banco de Dados'!A2:AF40,13,0) -> #N/A | AI38: =VLOOKUP(V38,'Banco de Dados'!A2:AF40,7,0) -> #N/A | AM38: =VLOOKUP(V38,'Banco de Dados'!A2:AI40,33,0) -> #N/A
V40: Tempo de Inatividade
V42: Aprendendo | AI42: TdI Gasto | AL42: TdI Necessário
AI43: 0
AI44: 0
AI45: 0
AI46: 0
AI47: 0
AI48: 0
AI49: 0
...

Sheet Jutsus
C2: 1 | D2: =Jutsu | J2: 0 | K2: Conhecidos pela Classe | S2: Ninjutsu | Y2: Genjutsu | AE2: Taijutsu | AK2: =Image("https://i.imgur.com/xr4aNbk.png") | AL2: =Fogo | AO2: =image("https://i.imgur.com/dhiYEei.png") | AP2: =Genjutsu
C3: 1 | D3: =Jutsu TdI | J3: 0 | K3: Ganhos da Classe | S3: =SUM(8,Ficha!X3+V7)+Modificadores!B57 -> 14 | U3: =SUM(Ficha!X3+V7)+Modificadores!B56 -> 6 | Y3: =SUM(8,Ficha!X3+AB7)+Modificadores!B59 -> 13 | AA3: =SUM(Ficha!X3+AB7)+Modificadores!B58 -> 5 | AE3: =SUM(8,Ficha!X3+AH7)+Modificadores!B61 -> 11 | AG3: =SUM(Ficha!X3+AH7)+Modificadores!B60 -> 3 | AK3: =Image("https://i.imgur.com/RHUlZn9.png") | AL3: =Vento | AO3: =image("https://i.imgur.com/IBa5vej.png") | AP3: =Taijutsu
C4: 2 | D4: =Jutsu Classe | J4: 0 | K4: Conhecidos do Clã | AK4: =Image("https://i.imgur.com/K1eHNGk.png") | AL4: =Água | AO4: =image("https://i.imgur.com/ctgTtMO.png") | AP4: =Bukijutsu
C5: 3 | D5: =Jutsu Talento | J5: 0 | K5: Aprendidos | S5: CD | ATAQUE | Y5: CD | ATAQUE | AE5: CD | ATAQUE | AK5: =Image("https://i.imgur.com/4Mq49oP.png") | AL5: =Relâmpago | AO5: =image("https://imgur.com/HjiOVvz.png") | AP5: =Medicinal
C6: 4 | D6: =Jutsu Clã | J6: 0 | K6: conhecido de Talentos | S6: Atributo | Y6: Atributo | AE6: Atributo | AK6: =IMAGE("https://i.imgur.com/OpSlY0k.png") | AL6: =Terra | AO6: =image("https://narutoacademy.weebly.com/uploads/3/0/1/7/301732/4472387.gif") | AP6: =Fuinjutsu
C7: 5 | D7: =Jutsu Recurso | J7: =SUM(J2:J6) -> 0 | K7: Total Jutsu Conhecidos | S7: Int | V7: =IF(S7="For",Ficha!C13,IF(S7="Des",Ficha!C18,IF(S7="Con",Ficha!C23,IF(S7="Int",Ficha!C28,IF(S7="Sab",Ficha!C33,Ficha!X16,IF(S7="Car",Ficha!C38,Ficha!X16)))))) -> 3 | Y7: Car | AB7: =IF(Y7="For",Ficha!C13,IF(Y7="Des",Ficha!C18,IF(Y7="Con",Ficha!C23,IF(Y7="Int",Ficha!C28,IF(Y7="Sab",Ficha!C33,IF(Y7="Car",Ficha!C38,)))))) -> 2 | AE7: For | AH7: =IF(AE7="For",Ficha!C13,IF(AE7="Des",Ficha!C18,IF(AE7="Con",Ficha!C23,IF(AE7="Int",Ficha!C28,IF(AE7="Sab",Ficha!C33,IF(AE7="Car",Ficha!C38,)))))) -> 0 | AK7: =image("https://i.imgur.com/66lADdK.png") | AL7: =Mistura | AO7: =image("https://cdn-icons-png.flaticon.com/512/33/33785.png") | AP7: =Nenhum
C8: Origem do Jutsu | AK8: Icone Chave
B10: 1
B11: Classificação | O11: Classificação | AB11: Classificação
B12: Rank: | D12: Rank E | H12: Custo | O12: Rank: | Q12: Rank E | U12: Custo | AB12: Rank: | AD12: Rank E | AH12: Custo
B13: Tempo de Conjuração | O13: Tempo de Conjuração | AB13: Tempo de Conjuração
B14: Alcance: | O14: Alcance: | AB14: Alcance:
B15: Duração: | O15: Duração: | AB15: Duração:
B16: Componentes: | O16: Componentes: | AB16: Componentes:
B17: Palavra-chave: | O17: Palavra-chave: | AB17: Palavra-chave:
B19: Em níveis superiores: | O19: Em níveis superiores: | AB19: Em níveis superiores:
B24: Classificação | O24: Classificação | AB24: Classificação
B25: Rank: | H25: Custo | O25: Rank: | U25: Custo | AB25: Rank: | AH25: Custo
B26: Tempo de Conjuração | O26: Tempo de Conjuração | AB26: Tempo de Conjuração
B27: Alcance: | O27: Alcance: | AB27: Alcance:
B28: Duração: | O28: Duração: | AB28: Duração:
B29: Componentes: | O29: Componentes: | AB29: Componentes:
B30: Palavra-chave: | O30: Palavra-chave: | AB30: Palavra-chave:
B32: Em níveis superiores: | O32: Em níveis superiores: | AB32: Em níveis superiores:
B37: Classificação | O37: Classificação | AB37: Classificação
B38: Rank: | H38: Custo | O38: Rank: | U38: Custo | AB38: Rank: | AH38: Custo
B39: Tempo de Conjuração | O39: Tempo de Conjuração | AB39: Tempo de Conjuração
B40: Alcance: | O40: Alcance: | AB40: Alcance:
B41: Duração: | O41: Duração: | AB41: Duração:
B42: Componentes: | O42: Componentes: | AB42: Componentes:
B43: Palavra-chave: | O43: Palavra-chave: | AB43: Palavra-chave:
B45: Em níveis superiores: | O45: Em níveis superiores: | AB45: Em níveis superiores:
B50: Classificação | O50: Classificação | AB50: Classificação
B51: Rank: | H51: Custo | O51: Rank: | U51: Custo | AB51: Rank: | AH51: Custo
B52: Tempo de Conjuração | O52: Tempo de Conjuração | AB52: Tempo de Conjuração
B53: Alcance: | O53: Alcance: | AB53: Alcance:
B54: Duração: | O54: Duração: | AB54: Duração:
B55: Componentes: | O55: Componentes: | AB55: Componentes:
B56: Palavra-chave: | O56: Palavra-chave: | AB56: Palavra-chave:
B58: Em níveis superiores: | O58: Em níveis superiores: | AB58: Em níveis superiores:
...

Sheet Classe
B2: Classe: | E2: =Ficha!M2 -> Ninja Batedor | P2: Jutsus Conhecidos:
B3: Sub-Classe: | E3: =Ficha!M4
B4: Mod Classe: | E4: =Ficha!M6 | P4: Recurso de Dado:
P6: Jutsu de Rank mais Alto:
B9: Caracteristicas:
C10: Estilo de Luta | P10: POSTURA DO PUNHO DO LOBO | AC10: Astucia (Explorador Habil)
B11: Nivel: | D11: 1 | H11: Custo: | O11: Nivel: | U11: Custo: | AB11: Nivel: | AD11: 1 | AH11: Custo:
B12: Descrição: | O12: Descrição: | AB12: Descrição:
B13: POSTURA DO PUNHO DO LOBO | O13: Seu dano desarmado se torna um d6. Seus ataques desarmados ganham propriedade de Bloqueio 1 de arma Como ação, você executa o Punho Presa do Lobo. Punho Presa de Lobo. Faça dois ataques desarmados, aumentando seu Dano Desarmado em +1. | AB13: Escolha uma habilidade qualquer. Você ganha proficiência nessa habilidade. Se já tiver proficiência nessa habilidade, em vez disso, você ganha Perícia.
B17: Nivel: | H17: Custo: | O17: Nivel: | U17: Custo: | AB17: Nivel: | AH17: Custo:
B18: Descrição: | O18: Descrição: | AB18: Descrição:
B22: Nivel: | H22: Custo: | O22: Nivel: | U22: Custo: | AB22: Nivel: | AH22: Custo:
B23: Descrição: | O23: Descrição: | AB23: Descrição:
B27: Nivel: | H27: Custo: | O27: Nivel: | U27: Custo: | AB27: Nivel: | AH27: Custo:
B28: Descrição: | O28: Descrição: | AB28: Descrição:
B32: Nivel: | H32: Custo: | O32: Nivel: | U32: Custo: | AB32: Nivel: | AH32: Custo:
B33: Descrição: | O33: Descrição: | AB33: Descrição:

Sheet Clã
B2: Clã: | E2: =Ficha!D4 -> Uchiha
B4: Caracteristicas:
C5: Liberação Fogo
B6: Nivel: | D6: 1 | H6: Custo: | O6: Nivel: | Q6: 1 | U6: Custo: | AB6: Nivel: | AH6: Custo:
B7: Descrição: | O7: Descrição: | AB7: Descrição:
B8: Enquanto você estiver ganhando os benefícios de sua característica Sharingan, uma vez por rodada, você pode realizar uma Reação adicional. Você pode fazer isso um número de vezes igual ao número de Tomoes do seu Sharingan, por descanso longo. | O8: Defesa Amplificada
B12: Nivel: | H12: Custo: | O12: Nivel: | U12: Custo: | AB12: Nivel: | AH12: Custo:
B13: Descrição: | O13: Descrição: | AB13: Descrição:
B17: Nivel: | H17: Custo: | O17: Nivel: | U17: Custo: | AB17: Nivel: | AH17: Custo:
B18: Descrição: | O18: Descrição: | AB18: Descrição:
B22: Nivel: | H22: Custo: | O22: Nivel: | U22: Custo: | AB22: Nivel: | AH22: Custo:
B23: Descrição: | O23: Descrição: | AB23: Descrição:
B27: Nivel: | H27: Custo: | O27: Nivel: | U27: Custo: | AB27: Nivel: | AH27: Custo:
B28: Descrição: | O28: Descrição: | AB28: Descrição:

Sheet Anotações
B2: Missões Completadas
B3: Rank D | E3: Rank C | H3: Rank B | K3: Rank A | N3: Rank S | Q3: Rank S+
B5: Anotações da missão
B7: Rank: | H7: Recompença: | O7: Rank: | U7: Recompença: | AB7: Rank: | AH7: Recompença:
B8: Tempo de inatividade: | J8: XP | O8: Tempo de inatividade: | W8: XP | AB8: Tempo de inatividade: | AJ8: XP
B9: Objetivo: | O9: Objetivo: | AB9: Objetivo:
B10: Anotações | O10: Anotações | AB10: Anotações
B15: Rank: | H15: Recompença: | O15: Rank: | U15: Recompença: | AB15: Rank: | AH15: Recompença:
B16: Tempo de inatividade: | J16: XP | O16: Tempo de inatividade: | W16: XP | AB16: Tempo de inatividade: | AJ16: XP
B17: Objetivo: | O17: Objetivo: | AB17: Objetivo:
B18: Anotações | O18: Anotações | AB18: Anotações
B23: Rank: | H23: Recompença: | O23: Rank: | U23: Recompença: | AB23: Rank: | AH23: Recompença:
B24: Tempo de inatividade: | J24: XP | O24: Tempo de inatividade: | W24: XP | AB24: Tempo de inatividade: | AJ24: XP
B25: Objetivo: | O25: Objetivo: | AB25: Objetivo:
B26: Anotações | O26: Anotações | AB26: Anotações
B31: Rank: | H31: Recompença: | O31: Rank: | U31: Recompença: | AB31: Rank: | AH31: Recompença:
B32: Tempo de inatividade: | J32: XP | O32: Tempo de inatividade: | W32: XP | AB32: Tempo de inatividade: | AJ32: XP
B33: Objetivo: | O33: Objetivo: | AB33: Objetivo:
B34: Anotações | O34: Anotações | AB34: Anotações
B39: Rank: | H39: Recompença: | O39: Rank: | U39: Recompença: | AB39: Rank: | AH39: Recompença:
B40: Tempo de inatividade: | J40: XP | O40: Tempo de inatividade: | W40: XP | AB40: Tempo de inatividade: | AJ40: XP
B41: Objetivo: | O41: Objetivo: | AB41: Objetivo:
B42: Anotações | O42: Anotações | AB42: Anotações
B47: Rank: | H47: Recompença: | O47: Rank: | U47: Recompença: | AB47: Rank: | AH47: Recompença:
B48: Tempo de inatividade: | J48: XP | O48: Tempo de inatividade: | W48: XP | AB48: Tempo de inatividade: | AJ48: XP
B49: Objetivo: | O49: Objetivo: | AB49: Objetivo:
B50: Anotações | O50: Anotações | AB50: Anotações
B55: Rank: | H55: Recompença: | O55: Rank: | U55: Recompença: | AB55: Rank: | AH55: Recompença:
B56: Tempo de inatividade: | J56: XP | O56: Tempo de inatividade: | W56: XP | AB56: Tempo de inatividade: | AJ56: XP
B57: Objetivo: | O57: Objetivo: | AB57: Objetivo:
B58: Anotações | O58: Anotações | AB58: Anotações

Sheet Invocação
C2: NOME: | P2: Informações | Y2: 40 | Z2: / | AD2: 0 | AK2: NOME: | AN2: =F2 | AU2: S-Rank
P3: Pontos ASI | Y3: HP | AD3: Temp HP | AK3: Traços da Função
P6: Força | AK6: Traços Rank D
P7: Base | S7: ASI | X7: CA | AB7: 0 | AD7: Velocidade
S8: 0
P9: Destreza | X9: JUTSU | AK9: Traços Rank C
P10: Base | S10: ASI
S11: 0 | AC11: 0
P12: Constituição | X12: Restante | AD12: Maximo | AK12: Traços Rank B
P13: Base | S13: ASI
S14: 0 | X14: JUTSU DA INVOCAÇÃO
P15: Inteligência | AA15: ⛰️ | AB15: Example Jutsu | AK15: Traços Rank A
P16: Base | S16: ASI | AA16: ☯ | AB16: Example Jutsu
S17: 0 | AA17: ☯ | AB17: Example Jutsu
C18: Animal | H18: Raposa | P18: Sabedoria | AA18: ☯ | AB18: Example Jutsu | AK18: Traços Rank S
C19: Tamanho: | H19: Medio | P19: Base | S19: ASI | AA19: ☯ | AB19: Example Jutsu
C20: Função: | H20: Defender | S20: 0 | AA20: ☯ | AB20: Example Jutsu
C21: Level da Invocação: | I21: º Level | P21: Carisma | AA21: ☯ | AB21: Example Jutsu | AK21: Traços Adicionais
C22: Tipo: | H22: =VLOOKUP(H18,'Banco de Dados'!B128:K152,6,0) -> Carnivoro | P22: Base | S22: ASI | AA22: ☯ | AB22: Example Jutsu
S23: 0
BI24: =IF(R[-20]C[130],CHOOSE(R[-3]C[-53],0,0,0,8,8,8,8,16,16,16,16,24,24,24,24,32,32,32,32,40) , IFS(R[-22]C[-14]="D-Rank",0,R[-22]C[-14]="C-Rank",6,R[-22]C[-14]="B-Rank",12,R[-22]C[-14]="A-Rank",18,R[-22]C[-14]="D-Rank",24))-R[-16]C[-42]-R[-13]C[-42]-R[-10]C[-42]-R[-7]C[-42]-R[-4]C[-42]-R[-1]C[-42] -> #ERROR!
C25: Arma Natural | Z25: Sentidos & Jutsu Opcionais | AN25: Salvamentos e habilidades
Z27: Sentidos
AQ29: DES | AW29: CON | BC29: CAR
Z30: Jutsu Selecionados
C31: FALSE
AN32: Atletismo | AR32: 0 | AT32: Atletismo | AX32: 0 | AY32: 0 | AZ32: Atletismo | BE32: 0 | BF32: History

Sheet Banco de Dados
A1: Nome da Armadura | G1: Tipo de Armadura | M1: Mod de Habilidade | Q1: Mod de Habilidade | U1: Mod max | Y1: Bônus da Armadura | AC1: CA final | AG1: Peso
A2: Roupa | G2: Armadura Leve | M2: DES | Q2: Nenhum | Y2: 0 | AC2: 0 | AG2: 0
A3: Pano acolchoado | G3: Armadura Leve | M3: DES | Q3: Nenhum | U3: 7 | Y3: 1 | AC3: =+1 -> 1 | AG3: 1
A4: Tecido de couro | G4: Armadura Leve | M4: DES | Q4: Nenhum | U4: 7 | Y4: 2 | AC4: =+2 -> 2 | AG4: 1
A5: Armadura Colchoada | G5: Armadura Leve | M5: DES | Q5: Nenhum | U5: 7 | Y5: 3 | AC5: =+3 -> 3 | AG5: 2
A6: Couro Reforçado | G6: Armadura Leve | M6: DES | Q6: Nenhum | U6: 7 | Y6: 3 | AC6: =+3 -> 3 | AG6: 2
A7: Tecido Sintético | G7: Armadura Leve | M7: DES | Q7: Nenhum | U7: 7 | Y7: 4 | AC7: =+4 -> 4 | AG7: 3
A8: Tecido Shinobi | G8: Armadura Leve | M8: DES | Q8: Nenhum | U8: 7 | Y8: 5 | AC8: =+5 -> 5 | AG8: 3
A9: Jaqueta de Combate | G9: Armadura Média | M9: DES | Q9: Nenhum | U9: 3 | Y9: 4 | AC9: =+4 -> 4 | AG9: 4
A10: Jaqueta Shinobi | G10: Armadura Média | M10: DES | Q10: Nenhum | U10: 3 | Y10: 4 | AC10: =+4 -> 4 | AG10: 3
A11: Jaqueta de combate Shinobi | G11: Armadura Média | M11: DES | Q11: Nenhum | U11: 3 | Y11: 5 | AC11: =+5 -> 5 | AG11: 4
A12: Jaqueta Chunin | G12: Armadura Média | M12: DES | Q12: Nenhum | U12: 3 | Y12: 5 | AC12: =+5 -> 5 | AG12: 5
A13: Casaco de Batalha | G13: Armadura Média | M13: DES | Q13: Nenhum | U13: 3 | Y13: 6 | AC13: =+6 -> 6 | AG13: 6
A14: Casaco Chunin Blindado | G14: Armadura Média | M14: DES | Q14: Nenhum | U14: 3 | Y14: 6 | AC14: =+6 -> 6 | AG14: 6
A15: Armadura de Combate | G15: Armadura Pesada | M15: Nenhum | Q15: Nenhum | U15: 0 | Y15: 6 | AC15: =+6 -> 6 | AG15: 6
A16: Armadura Sintética | G16: Armadura Pesada | M16: Nenhum | Q16: Nenhum | U16: 0 | Y16: 6 | AC16: =+6 -> 6 | AG16: 5
A17: Armadura Jounin | G17: Armadura Pesada | M17: Nenhum | Q17: Nenhum | U17: 0 | Y17: 7 | AC17: =+7 -> 7 | AG17: 4
A18: Armadura de Elite Jounin | G18: Armadura Pesada | M18: Nenhum | Q18: Nenhum | U18: 0 | Y18: 7 | AC18: =+7 -> 7 | AG18: 6
A19: Armadura Ronin | G19: Armadura Pesada | M19: Nenhum | Q19: Nenhum | U19: 0 | Y19: 8 | AC19: =+8 -> 8 | AG19: 6
A20: Armadura Samurai | G20: Armadura Pesada | M20: Nenhum | Q20: Nenhum | U20: 0 | Y20: 8 | AC20: =+8 -> 8 | AG20: 8
A21: Pele de Chakra | G21: Mod Habilidade | M21: INT | Q21: Nenhum | Y21: 3 | AC21: =+3 -> 3 | AG21: 0
A22: Pele de Chakra (Rank B) | G22: Mod Habilidade | M22: INT | Q22: Nenhum | Y22: 4 | AC22: =+4 -> 4 | AG22: 0
A23: Pele de Chakra (Rank S) | G23: Mod Habilidade | M23: INT | Q23: Nenhum | Y23: 5 | AC23: =+5 -> 5 | AG23: 0
A24: Camada de poeira | G24: Mod Habilidade | M24: INT | Q24: PROF | Y24: 3 | AC24: =+6 -> 6 | AG24: 0
A25: Camada de poeira (Rank B) | G25: Mod Habilidade | M25: INT | Q25: PROF | Y25: 4 | AC25: =+7 -> 7 | AG25: 0
A26: Camada de poeira (Rank S) | G26: Mod Habilidade | M26: INT | Q26: PROF | Y26: 5 | AC26: =+8 -> 8 | AG26: 0
A27: Cota de malha | G27: Personalizado | M27: DES | Q27: INT | Y27: 0 | AC27: 0 | AG27: 0
A28: Terno de madeira | G28: Armadura Leve | M28: DES | Q28: Nenhum | Y28: 3 | AC28: =+3 -> 3 | AG28: 3
A29: Concha de Ferro | G29: Armadura Média | M29: DES | Q29: Nenhum | U29: 2 | Y29: 5 | AC29: =+5 -> 5 | AG29: 6
A30: Fortaleza de Aço | G30: Armadura Pesada | M30: Nenhum | Q30: Nenhum | U30: 0 | Y30: 8 | AC30: =+8 -> 8 | AG30: 8
A31: Geo-Peitoral (Inteligência) | G31: Mod Habilidade | M31: INT | Q31: Nenhum | Y31: 3 | AC31: =+3 -> 3 | AG31: 0
A32: Geo-Peitoral (Constituição) | G32: Mod Habilidade | M32: CON | Q32: Nenhum | Y32: 3 | AC32: =+3 -> 3 | AG32: 0
A33: Defesa Marcial | G33: Mod Habilidade | M33: DES | Q33: PROF | Y33: 0 | AC33: =+3 -> 3 | AG33: 0
A34: [[Custom Armor Below Here]] | G34: ====================== -> #ERROR! | M34: ============== -> #ERROR! | Q34: ============== -> #ERROR!
G35: Custom
G36: Custom
G37: Custom
G38: Custom
G39: Custom
G40: Custom
...

Sheet Modificadores
A1: Modificador | E1: Mod de Classe | Y1: =IFERROR(__xludf.DUMMYFUNCTION("filter(Z:Z,countif(AA:AA,Z:Z)<1)"),"") | Z1: =if(I2,getAllSheetNames(),"") | AA1: Instructions
A2: Modificando | B2: Total | C2: Entrada Manual | D2: Condições | AA2: Character Info
A3: PV Max | B3: =sum(C3:G3) -> 10 | D3: 10 | AA3: Extra Character Info
A4: Chakra Max | B4: =sum(C4:G4) -> 10 | D4: 10 | AA4: Puppet Master Sheet (2024)
A5: Dado de Vida | B5: =sum(C5:G5) -> 0 | K5: 2 | AA5: Combat Unification
A6: Dado de Chakra | B6: =sum(C6:G6) -> 0 | AA6: Summon Sheet
A7: CA | B7: =sum(C7:G7) -> 0 | D7: =-Ficha!AV41*Ficha!AW41-Ficha!AV34*Ficha!AW34 -> 0 | AA7: Jutsu Cards
A8: Iniciativa | B8: =sum(C8:G8) -> 0 | D8: =-Ficha!AV41*Ficha!AW41-Ficha!AV31*Ficha!AW31 -> 0 | AA8: Allies Status Sheet (Optional)
A9: Mov (base) | B9: =sum(C9:G9) -> 0 | D9: =-ROUNDDOWN(Ficha!AV41*Ficha!AW41/2,0.5)*1.5-(Ficha!AV31*Ficha!AW31*1.5)+IF(Ficha!AN37=true,K5=1,0)-(Ficha!AN45*Ficha!AO45*3) -> 0 | AA9: Lists
A10: Prof | B10: =sum(C10:G10) -> 0 | AA10: ClassChartgen
A11: FOR | B11: =sum(C11:G11) -> 0 | AA11: Puppet Master Sheet (v5.0.0) (Beta)
A12: FOR fixo | B12: =sum(C12:G12) -> 0 | AA12: How to add Homebrew stuff
A13: DES | B13: =sum(C13:G13) -> 0 | AA13: Jutsu Sheet
A14: DES fixa | B14: =max(C14:G14) -> 0 | AA14: Jutsu List (Courtesy of Kane)
A15: CON | B15: =sum(C15:G15) -> 0 | AA15: Feature Lookup
A16: CON fixo | B16: =max(C16:G16) -> 0 | AA16: Modified Extra Modules
A17: INT | B17: =sum(C17:G17) -> 0 | AA17: Jovian's Extra Modules
A18: INT fixa | B18: =max(C18:G18) -> 0 | AA18: Clan Insert Sheet
A19: SAB | B19: =sum(C19:G19) -> 0 | AA19: Class Insert Sheet
A20: SAB fixa | B20: =max(C20:G20) -> 0 | AA20: Subclass Insert Sheet
A21: CAR | B21: =sum(C21:G21) -> 0 | AA21: Homebrew Insert Sheet
A22: CAR fixa | B22: =max(C22:G22) -> 0 | AA22: Plug Sheet
A23: FOR resitência | B23: =max(C23:G23) -> 0 | D23: =-Ficha!AN39*Ficha!AO39 -> 0 | AA23: Change Log
A24: DES resitência | B24: =max(C24:G24) -> 0 | D24: =-Ficha!AV31*Ficha!AW31 -> 0 | AA24: Basebook Jutsu + Info List
A25: CON resitência | B25: =max(C25:G25) -> 0 | D25: =-Ficha!AV32*Ficha!AW32 -> 0
A26: INT resitência | B26: =max(C26:G26) -> 0 | D26: =-Ficha!AN42*Ficha!AO42 -> 0
A27: SAB resitência | B27: =max(C27:G27) -> 0 | D27: =-Ficha!AN43*Ficha!AO43 -> 0
A28: CAR resitência | B28: =max(C28:G28) -> 0 | D28: =-Ficha!AN40*Ficha!AO40 -> 0
A29: TODAS as res | B29: =max(C29:G29) -> 0 | D29: =-Ficha!AV41*Ficha!AW41-Ficha!AN44*Ficha!AO44 -> 0
A30: Acrobacia | B30: =max(C30:G30) -> 0 | D30: =-Ficha!AV31*Ficha!AW31-Ficha!AN30*Ficha!AO31 -> 0
A31: Adestrar Animais | B31: =max(C31:G31) -> 0 | D31: =-Ficha!AN43*Ficha!AO43 -> 0
A32: Artes Marciais | B32: =max(C32:G32) -> 0 | D32: =-Ficha!AN30*Ficha!AO30 -> 0
A33: Atletismo | B33: =max(C33:G33) -> 0 | D33: =-Ficha!AN30*Ficha!AO30 -> 0
A34: Construir | B34: =max(C34:G34) -> 0 | D34: =-Ficha!AN42*Ficha!AO42 -> 0
A35: Controle de Chakra | B35: =max(C35:G35) -> 0 | D35: =-Ficha!AV32*Ficha!AW32-Ficha!AN30*Ficha!AO30 -> 0
A36: Decepção | B36: =max(C36:G36) -> 0
A37: Furtividade | B37: =max(C37:G37) -> 0 | D37: =-Ficha!AV31*Ficha!AW31-Ficha!AN30*Ficha!AO31 -> 0
A38: História | B38: =max(C38:G38) -> 0 | D38: =-Ficha!AN42*Ficha!AO42 -> 0
A39: Ilusão | B39: =max(C39:G39) -> 0 | D39: =-Ficha!AN43*Ficha!AO43 -> 0
A40: Intimidação | B40: =max(C40:G40) -> 0
...
